sqlalchemy.exc.ProgrammingError: (psycopg2.errors.UndefinedColumn) column user.is_active does not exist
[parameters: {'username_1': 'hamka', 'email_1': 'hamka.sulaiman@gmail.com', 'param_1': 1}]
  File "/app/photovault/utils/__init__.py", line 79, in execute_query
(Background on this error at: https://sqlalche.me/e/20/f405)
LINE 1: ...sword_hash, "user".created_at AS user_created_at, "user".is_...
100.64.0.2 - - [25/Sep/2025:15:59:19 +0000] "POST /auth/register HTTP/1.1" 500 265 "https://photoverone-production-c5dd.up.railway.app/auth/register" "Mozilla/5.0 (Windows NT 10.0; Win64; x64) AppleWebKit/537.36 (KHTML, like Gecko) Chrome/140.0.0.0 Safari/537.36 Edg/140.0.0.0"
    return query_func()
                                                             ^
           ^^^^^^^^^^^^
  File "/app/photovault/routes/auth.py", line 128, in check_existing_user
[SQL: SELECT "user".id AS user_id, "user".username AS user_username, "user".email AS user_email, "user".password_hash AS user_password_hash, "user".created_at AS user_created_at, "user".is_active AS user_is_active, "user".is_admin AS user_is_admin, "user".is_superuser AS user_is_superuser 
FROM "user" 
    ).first()
WHERE "user".username = %(username_1)s OR "user".email = %(email_1)s 
      ^^^^^^^
  File "/opt/venv/lib/python3.11/site-packages/sqlalchemy/orm/query.py", line 2748, in first
 LIMIT %(param_1)s]
    return self.limit(1)._iter().first()  # type: ignore
           ^^^^^^^^^^^^^^^^^^^^^
  File "/opt/venv/lib/python3.11/site-packages/sqlalchemy/orm/query.py", line 2847, in _iter
    result: Union[ScalarResult[_T], Result[_T]] = self.session.execute(
                                                  ^^^^^^^^^^^^^^^^^^^^^
  File "/opt/venv/lib/python3.11/site-packages/sqlalchemy/orm/session.py", line 2308, in execute
    return self._execute_internal(
           ^^^^^^^^^^^^^^^^^^^^^^^
  File "/opt/venv/lib/python3.11/site-packages/sqlalchemy/orm/session.py", line 2190, in _execute_internal
    result: Result[Any] = compile_state_cls.orm_execute_statement(
                          ^^^^^^^^^^^^^^^^^^^^^^^^^^^^^^^^^^^^^^^^
  File "/opt/venv/lib/python3.11/site-packages/sqlalchemy/orm/context.py", line 293, in orm_execute_statement
    result = conn.execute(
             ^^^^^^^^^^^^^
  File "/opt/venv/lib/python3.11/site-packages/sqlalchemy/engine/base.py", line 1416, in execute
    return meth(
           ^^^^^
  File "/opt/venv/lib/python3.11/site-packages/sqlalchemy/sql/elements.py", line 517, in _execute_on_connection
    return connection._execute_clauseelement(
           ^^^^^^^^^^^^^^^^^^^^^^^^^^^^^^^^^^
  File "/opt/venv/lib/python3.11/site-packages/sqlalchemy/engine/base.py", line 1639, in _execute_clauseelement
    ret = self._execute_context(
          ^^^^^^^^^^^^^^^^^^^^^^
  File "/opt/venv/lib/python3.11/site-packages/sqlalchemy/engine/base.py", line 1848, in _execute_context
    return self._exec_single_context(
           ^^^^^^^^^^^^^^^^^^^^^^^^^^
  File "/opt/venv/lib/python3.11/site-packages/sqlalchemy/engine/base.py", line 1988, in _exec_single_context
    self._handle_dbapi_exception(
  File "/opt/venv/lib/python3.11/site-packages/sqlalchemy/engine/base.py", line 2344, in _handle_dbapi_exception
    raise sqlalchemy_exception.with_traceback(exc_info[2]) from e
  File "/opt/venv/lib/python3.11/site-packages/sqlalchemy/engine/base.py", line 1969, in _exec_single_context
    self.dialect.do_execute(
  File "/opt/venv/lib/python3.11/site-packages/sqlalchemy/engine/default.py", line 922, in do_execute
    cursor.execute(statement, parameters)
