Traceback (most recent call last):
  File "/home/runner/workspace/.pythonlibs/lib/python3.11/site-packages/flask/app.py", line 1473, in wsgi_app
    response = self.full_dispatch_request()
               ^^^^^^^^^^^^^^^^^^^^^^^^^^^^
  File "/home/runner/workspace/.pythonlibs/lib/python3.11/site-packages/flask/app.py", line 882, in full_dispatch_request
    rv = self.handle_user_exception(e)
         ^^^^^^^^^^^^^^^^^^^^^^^^^^^^^
  File "/home/runner/workspace/.pythonlibs/lib/python3.11/site-packages/flask/app.py", line 880, in full_dispatch_request
    rv = self.dispatch_request()
         ^^^^^^^^^^^^^^^^^^^^^^^
  File "/home/runner/workspace/.pythonlibs/lib/python3.11/site-packages/flask/app.py", line 865, in dispatch_request
    return self.ensure_sync(self.view_functions[rule.endpoint])(**view_args)  # type: ignore[no-any-return]
           ^^^^^^^^^^^^^^^^^^^^^^^^^^^^^^^^^^^^^^^^^^^^^^^^^^^^^^^^^^^^^^^^^
  File "/home/runner/workspace/.pythonlibs/lib/python3.11/site-packages/flask_login/utils.py", line 290, in decorated_view
    return current_app.ensure_sync(func)(*args, **kwargs)
           ^^^^^^^^^^^^^^^^^^^^^^^^^^^^^^^^^^^^^^^^^^^^^^
  File "/home/runner/workspace/photovault/routes/family.py", line 128, in view_vault
    return render_template('family/vault_detail.html',
           ^^^^^^^^^^^^^^^^^^^^^^^^^^^^^^^^^^^^^^^^^^^
  File "/home/runner/workspace/.pythonlibs/lib/python3.11/site-packages/flask/templating.py", line 150, in render_template
    return _render(app, template, context)
           ^^^^^^^^^^^^^^^^^^^^^^^^^^^^^^^
  File "/home/runner/workspace/.pythonlibs/lib/python3.11/site-packages/flask/templating.py", line 131, in _render
    rv = template.render(context)
         ^^^^^^^^^^^^^^^^^^^^^^^^
  File "/home/runner/workspace/.pythonlibs/lib/python3.11/site-packages/jinja2/environment.py", line 1304, in render
    self.environment.handle_exception()
  File "/home/runner/workspace/.pythonlibs/lib/python3.11/site-packages/jinja2/environment.py", line 939, in handle_exception
    raise rewrite_traceback_stack(source=source)
  File "/home/runner/workspace/photovault/templates/family/vault_detail.html", line 1, in top-level template code
    {% extends "base.html" %}
  File "/home/runner/workspace/photovault/templates/base.html", line 232, in top-level template code
    {% block content %}{% endblock %}
    ^^^^^^^^^^^^^^^^^^^^^^^^^
  File "/home/runner/workspace/photovault/templates/family/vault_detail.html", line 149, in block 'content'
    window.location.href = "{{ url_for('family.view_vault_photo', vault_id=vault.id, vault_photo_id='__PHOTO_ID__') }}".replace('__PHOTO_ID__', vaultPhotoId);
    ^^^^^^^^^^^^^^^^^^^^^^^^^
  File "/home/runner/workspace/.pythonlibs/lib/python3.11/site-packages/flask/app.py", line 1073, in url_for
    rv = url_adapter.build(  # type: ignore[union-attr]
         ^^^^^^^^^^^^^^^^^^^^^^^^^^^^^^^^^^^^^^^^^^^^^^
  File "/home/runner/workspace/.pythonlibs/lib/python3.11/site-packages/werkzeug/routing/map.py", line 922, in build
    rv = self._partial_build(endpoint, values, method, append_unknown)
         ^^^^^^^^^^^^^^^^^^^^^^^^^^^^^^^^^^^^^^^^^^^^^^^^^^^^^^^^^^^^^
  File "/home/runner/workspace/.pythonlibs/lib/python3.11/site-packages/werkzeug/routing/map.py", line 801, in _partial_build
    rv = self._partial_build(
         ^^^^^^^^^^^^^^^^^^^^
  File "/home/runner/workspace/.pythonlibs/lib/python3.11/site-packages/werkzeug/routing/map.py", line 814, in _partial_build
    build_rv = rule.build(values, append_unknown)
               ^^^^^^^^^^^^^^^^^^^^^^^^^^^^^^^^^^
  File "/home/runner/workspace/.pythonlibs/lib/python3.11/site-packages/werkzeug/routing/rules.py", line 839, in build
    return self._build_unknown(**values)
           ^^^^^^^^^^^^^^^^^^^^^^^^^^^^^
  File "<werkzeug routing>", line 1, in <builder:'/family/vault/<int:vault_id>/photo/<int:vault_photo_id>'>
  File "/home/runner/workspace/.pythonlibs/lib/python3.11/site-packages/werkzeug/routing/converters.py", line 163, in to_url
    value_str = str(self.num_convert(value))
                    ^^^^^^^^^^^^^^^^^^^^^^^
ValueError: invalid literal for int() with base 10: '__PHOTO_ID__'
INFO:werkzeug:172.31.82.98 - - [22/Sep/2025 13:22:50] "GET /family/vault/1 HTTP/1.1" 500 -