  File "/opt/venv/lib/python3.11/site-packages/sqlalchemy/engine/base.py", line 1969, in _exec_single_context
    self.dialect.do_execute(
  File "/opt/venv/lib/python3.11/site-packages/sqlalchemy/engine/default.py", line 922, in do_execute
    cursor.execute(statement, parameters)
psycopg2.errors.DuplicateColumn: column "description" of relation "photo" already exists
The above exception was the direct cause of the following exception:
Traceback (most recent call last):
  File "<frozen runpy>", line 198, in _run_module_as_main
  File "<frozen runpy>", line 88, in _run_code
  File "/opt/venv/lib/python3.11/site-packages/flask/__main__.py", line 3, in <module>
    main()
  File "/opt/venv/lib/python3.11/site-packages/flask/cli.py", line 1105, in main
    cli.main()
  File "/opt/venv/lib/python3.11/site-packages/click/core.py", line 1078, in main
    rv = self.invoke(ctx)
         ^^^^^^^^^^^^^^^^
  File "/opt/venv/lib/python3.11/site-packages/click/core.py", line 1688, in invoke
    return _process_result(sub_ctx.command.invoke(sub_ctx))
                           ^^^^^^^^^^^^^^
^^^^^^^^^^^^^^^^^
  File "/opt/venv/lib/python3.11/site-packages/click/core.py", line 1688, in invoke
    return _process_result(sub_ctx.command.invoke(sub_ctx))
                           ^^^^^^^^^^^^^^^^^^^^^^^^^^^^^^^
  File "/opt/venv/lib/python3.11/site-packages/click/core.py", line 1434, in invoke
    return ctx.invoke(self.callback, **ctx.params)
           ^^^^^^^^^^^^^^^^^^^^^^^^^^^^^^^^^^^^^^^
  File "/opt/venv/lib/python3.11/site-packages/click/core.py", line 783, in invoke
    return __callback(*args, **kwargs)
           ^^^^^^^^^^^^^^^^^^^^^^^^^^^
  File "/opt/venv/lib/python3.11/site-packages/click/decorators.py", line 33, in new_func
    return f(get_current_context(), *args, **kwargs)
           ^^^^^^^^^^^^^^^^^^^^^^^^^^^^^^^^^^^^^^
^^^
  File "/opt/venv/lib/python3.11/site-packages/flask/cli.py", line 386, in decorator
    return ctx.invoke(f, *args, **kwargs)
           ^^^^^^^^^^^^^^^^^^^^^^^^^^^^^^
  File "/opt/venv/lib/python3.11/site-packages/click/core.py", line 783, in invoke
    return __callback(*args, **kwargs)
           ^^^^^^^^^^^^^^^^^^^^^^^^^^^
  File "/opt/venv/lib/python3.11/site-packages/flask_migrate/cli.py", line 157, in upgrade
    _upgrade(directory or g.directory, revision, sql, tag, x_arg or g.x_arg)
  File "/opt/venv/lib/python3.11/site-packages/flask_migrate/__init__.py", line 111, in wrapped
    f(*args, **kwargs)
  File "/opt/venv/lib/python3.11/site-packages/flask_migrate/__init__.py", line 200, in upgrade
    command.upgrade(config, revision, sql=sql, tag=tag)
  File "/opt/venv/lib/python3.11/site-packages/alembic/command.py", line 403, in upgrade
    script.run_env()
  File "/opt/venv/lib/python3.11/site-packages/alembic/script/base.py", line 583, in run_env
    util.load_python_file(self.dir, "env.py")
  File "/opt/venv/lib/python3.11/site-packages/alembic/util/pyfiles.py", line 95, in load_python_file
    module = load_module_py(module_id, path)
             ^^^^^^^^^^^^^^^^^^^^^^^^^^^^^^^
  File "/opt/venv/lib/python3.11/site-packages/alembic/util/pyfiles.py", line 113, in load_module_py
    spec.loader.exec_module(module)  # type: ignore
    ^^^^^^^^^^^^^^^^^^^^^^^^^^^^^^^
  File "<frozen importlib._bootstrap_external>", line 940, in exec_module
  File "<frozen importlib._bootstrap>", line 241, in _call_with_frames_removed
  File "/app/migrations/env.py", line 113, in <module>
    run_migrations_online()
  File "/app/migrations/env.py", line 107, in run_migrations_online
    context.run_migrations()
  File "<string>", line 8, in run_migrations
  File "/opt/venv/lib/python3.11/site-packages/alembic/runtime/environment.py", line 948, in run_migrations
    self.get_context().run_migrations(**kw)
  File "/opt/venv/lib/python3.11/site-packages/alembic/runtime/migration.py", line 627, in run_migrations
    step.migration_fn(**kw)
  File "/app/migrations/versions/4d9b1047e584_add_missing_photo_metadata_columns.py", line 43, in upgrade
    op.add_column('photo', sa.Column('description', sa.Text(), nullable=True))
  File "<string>", line 8, in add_column
  File "<string>", line 3, in add_column
  File "/opt/venv/lib/python3.11/site-packages/alembic/operations/ops.py", line 2142, in add_column
    return operations.invoke(op)
           ^^^^^^^^^^^^^^^^^^^^^
  File "/opt/venv/lib/python3.11/site-packages/alembic/operations/base.py", line 445, in invoke
    return fn(self, operation)
           ^^^^^^^^^^^^^^^^^^^
  File "/opt/venv/lib/python3.11/site-packages/alembic/operations/toimpl.py", line 171, in add_column
    operations.impl.add_column(table_name, column, schema=schema, **kw)
  File "/opt/venv/lib/python3.11/site-packages/alembic/ddl/impl.py", line 334, in add_column
    self._exec(base.AddColumn(table_name, column, schema=schema))
  File "/opt/venv/lib/python3.11/site-packages/alembic/ddl/impl.py", line 207, in _exec
    return conn.execute(construct, multiparams)
           ^^^^^^^^^^^^^^^^^^^^^^^^^^^^^^^^^^^^
  File "/opt/venv/lib/python3.11/site-packages/sqlalchemy/engine/base.py", line 1416, in execute
    return meth(
           ^^^^^
  File "/opt/venv/lib/python3.11/site-packages/sqlalchemy/sql/ddl.py", line 181, in _execute_on_connection
    return connection._execute_ddl(
           ^^^^^^^^^^^^^^^^^^^^^^^^
  File "/opt/venv/lib/python3.11/site-packages/sqlalchemy/engine/base.py", line 1528, in _execute_ddl
    ret = self._execute_context(
          ^^^^^^^^^^^^^^^^^^^^^^
  File "/opt/venv/lib/python3.11/site-packages/sqlalchemy/engine/base.py", line 1848, in _execute_context
    return self._exec_single_context(
           ^^^^^^^^^^^^^^^^^^^^^^^^^^
  File "/opt/venv/lib/python3.11/site-packages/sqlalchemy/engine/base.py", line 1988, in _exec_single_context
    self._handle_dbapi_exception(
  File "/opt/venv/lib/python3.11/site-packages/sqlalchemy/engine/base.py", line 2344, in _handle_dbapi_exception
    raise sqlalchemy_exception.with_traceback(exc_info[2]) from e
  File "/opt/venv/lib/python3.11/site-packages/sqlalchemy/engine/base.py", line 1969, in _exec_single_context
    self.dialect.do_execute(
  File "/opt/venv/lib/python3.11/site-packages/sqlalchemy/engine/default.py", line 922, in do_execute
    cursor.execute(statement, parameters)
sqlalchemy.exc.ProgrammingError: (psycopg2.errors.DuplicateColumn) column "description" of relation "photo" already exists
[SQL: ALTER TABLE photo ADD COLUMN description TEXT]
(Background on this error at: https://sqlalche.me/e/20/f405)
Stopping Container