  File "/app/.venv/lib/python3.11/site-packages/sqlalchemy/engine/create.py", line 645, in connect
  File "/app/.venv/lib/python3.11/site-packages/sqlalchemy/pool/base.py", line 902, in __connect
    conn = _connect(dsn, connection_factory=connection_factory, **kwasync)
    return self.loaded_dbapi.connect(*cargs, **cparams)
           ^^^^^^^^^^^^^^^^^^^^^^^^^
  File "/app/.venv/lib/python3.11/site-packages/flask_login/utils.py", line 284, in decorated_view
  File "/app/.venv/lib/python3.11/site-packages/sqlalchemy/pool/impl.py", line 169, in _do_get
    return dialect.connect(*cargs, **cparams)
connection to server at "postgres.railway.internal" (fd12:cd56:e531:0:9000:36:5f36:29a), port 5432 failed: FATAL:  password authentication failed for user "postgres"
           ^^^^^^^^^^^^^^^^^^^^^^^^^^^^^^^^^^^^^^^^^^^^
           ^^^^^^^^^^^^^^^^^^^^^^^^^^^^^^^^^^^^^^^^^^^^^^^^^^^^^^^^^^^^^^^
    elif not current_user.is_authenticated:
  File "/app/.venv/lib/python3.11/site-packages/sqlalchemy/pool/base.py", line 393, in _create_connection
    with util.safe_reraise():
             ^^^^^^^^^^^^^^^^^^^^^^^^^^^^^
    return _ConnectionRecord(self)
(Background on this error at: https://sqlalche.me/e/20/e3q8)
sqlalchemy.exc.OperationalError: (psycopg2.OperationalError) connection to server at "postgres.railway.internal" (fd12:cd56:e531:0:9000:36:5f36:29a), port 5432 failed: FATAL:  password authentication failed for user "postgres"
           ^^^^^^^^^^^^^^^^^^^^^^^
  File "/app/.venv/lib/python3.11/site-packages/werkzeug/local.py", line 318, in __get__
  File "/app/.venv/lib/python3.11/site-packages/sqlalchemy/pool/base.py", line 678, in __init__
    obj = instance._get_current_object()
    self.__connect()
          ^^^^^^^^^^^^^^^^^^^^^^^^^^^^^^
  File "/app/.venv/lib/python3.11/site-packages/sqlalchemy/pool/base.py", line 902, in __connect
    with util.safe_reraise():
  File "/app/.venv/lib/python3.11/site-packages/sqlalchemy/util/langhelpers.py", line 146, in __exit__
    raise exc_value.with_traceback(exc_tb)
  File "/app/.venv/lib/python3.11/site-packages/sqlalchemy/pool/base.py", line 898, in __connect
    self.dbapi_connection = connection = pool._invoke_creator(self)
                                         ^^^^^^^^^^^^^^^^^^^^^^^^^^
  File "/app/.venv/lib/python3.11/site-packages/sqlalchemy/engine/create.py", line 645, in connect
    return dialect.connect(*cargs, **cparams)
           ^^^^^^^^^^^^^^^^^^^^^^^^^^^^^^^^^^
  File "/app/.venv/lib/python3.11/site-packages/sqlalchemy/engine/default.py", line 616, in connect
    return self.loaded_dbapi.connect(*cargs, **cparams)
           ^^^^^^^^^^^^^^^^^^^^^^^^^^^^^^^^^^^^^^^^^^^^
  File "/app/.venv/lib/python3.11/site-packages/psycopg2/__init__.py", line 122, in connect
    conn = _connect(dsn, connection_factory=connection_factory, **kwasync)
           ^^^^^^^^^^^^^^^^^^^^^^^^^^^^^^^^^^^^^^^^^^^^^^^^^^^^^^^^^^^^^^^
psycopg2.OperationalError: connection to server at "postgres.railway.internal" (fd12:cd56:e531:0:9000:36:5f36:29a), port 5432 failed: FATAL:  password authentication failed for user "postgres"
connection to server at "postgres.railway.internal" (fd12:cd56:e531:0:9000:36:5f36:29a), port 5432 failed: FATAL:  password authentication failed for user "postgres"